<?xml version="1.0"?>
<robot name="THOR_arm">

  <!-- Link robot base -->
  <link name="base">
    <visual>
      <origin xyz="0 0 0" rpy="0 0 0"/>
      <geometry>
        <mesh filename="package://urdf_thor/meshes/base.stl" scale="0.001 0.001 0.001" />
      </geometry>
      <material name="filament">
        <color rgba="0.69803922 0.82352941 0.94117647 1.0"/> <!-- rgba="178 210 240 255"/-->
      </material>
    </visual>
    <collision>
      <origin xyz="0 0 0.066" rpy="0 0 0"/> 
      <geometry>
        <cylinder radius="0.096" length="0.132"/>
      </geometry>
    </collision>
  </link>

  <!-- Joint base_art1 -->
  <joint name="art1_yaw" type="revolute">
    <origin xyz="0 0 0.104" rpy="0 0 0"/>
    <axis xyz="0 0 1"/>
    <parent link="base"/>
    <child link="art1"/>
    <limit lower="-3.1415" upper="3.1415" effort="4" velocity="1" />
  </joint>

  <!-- Link art1 -->
  <link name="art1">
    <visual>
      <origin xyz="0 0 0" rpy="0 0 0" />
      <geometry>
        <mesh filename="package://urdf_thor/meshes/art1.stl" scale="0.001 0.001 0.001" />
      </geometry>
      <material name="filament"/>
    </visual>
    <collision>
      <origin xyz="0 0 0.07" rpy="0 0 0"/> 
        <geometry>
          <box size="0.14 0.09 0.14"/>
        </geometry>
    </collision>
  </link>
  
  <!-- Joint art1_art2 -->
  <joint name="art2_pitch" type="revolute">
    <origin xyz="0 -0.0318752 0.0974304" rpy="1.5707963267948966 -1.5707963267948966 0"/>
    <axis xyz="0 0 1"/>
    <parent link="art1"/>
    <child link="art2"/>
    <limit lower="-1.5707963267948966" upper="1.5707963267948966" effort="4" velocity="1" />
  </joint>

  <!-- Link art2 -->
  <link name="art2">
    <visual>
      <origin xyz="0 0 0" rpy="0 0 0" />
      <geometry>
        <mesh filename="package://urdf_thor/meshes/art2.stl" scale="0.001 0.001 0.001" />
      </geometry>
      <material name="filament"/>
    </visual>
  </link>

  <!-- Joint art2_art3 -->
  <joint name="art3_pitch" type="revolute">
    <origin xyz="0.160 0 0" rpy="0 0 0"/>
    <axis xyz="0 0 1"/>
    <parent link="art2"/>
    <child link="art3"/>
    <limit lower="-1.5707963267948966" upper="1.5707963267948966" effort="4" velocity="1" />
  </joint>

  <!-- Link art3 -->
  <link name="art3">
    <visual>
      <origin xyz="0 0 0" rpy="0 0 0" />
      <geometry>
        <mesh filename="package://urdf_thor/meshes/art3.stl" scale="0.001 0.001 0.001" />
      </geometry>
      <material name="filament"/>
    </visual>
  </link>
  
  <!-- Joint art3_art4 -->
  <joint name="art4_roll" type="revolute">
    <origin xyz="0.0885 0 -0.035" rpy="0 1.5707963267948966 0"/>
    <axis xyz="0 0 1"/>
    <parent link="art3"/>
    <child link="art4"/>
    <limit lower="-3.1415" upper="3.1415" effort="4" velocity="1" />
  </joint>

  <!-- Link art4 -->
  <link name="art4">
    <visual>
      <origin xyz="0 0 0" rpy="0 0 0" />
      <geometry>
        <mesh filename="package://urdf_thor/meshes/art4.stl" scale="0.001 0.001 0.001" />
      </geometry>
      <material name="filament"/>
    </visual>
  </link>

  <!-- Joint art4_art5 -->
  <joint name="art5_pitch" type="revolute">
    <origin xyz="0 0 0.1" rpy="0 -1.5707963267948966 0"/>
    <axis xyz="0 0 1"/>
    <parent link="art4"/>
    <child link="art5"/>
    <limit lower="-1.5" upper="1.5" effort="4" velocity="1" /> <!-- Slightly less than right angle -->
  </joint>

  <!-- Link art5 -->
  <link name="art5">
    <visual>
      <origin xyz="0 0 0" rpy="0 0 0" />
      <geometry>
        <mesh filename="package://urdf_thor/meshes/art5.stl" scale="0.001 0.001 0.001" />
      </geometry>
      <material name="filament"/>
    </visual>
  </link>

  <!-- Joint art5_art6 -->
  <joint name="art6_roll" type="revolute">
    <origin xyz="0 0 0" rpy="0 1.5707963267948966 0"/>
    <axis xyz="0 0 1"/>
    <parent link="art5"/>
    <child link="art6"/>
    <limit lower="-3.1415" upper="3.1415" effort="4" velocity="1" />
  </joint>

  <!-- Link art6 -->
  <link name="art6">
    <visual>
      <origin xyz="0 0 0" rpy="0 0 0" />
      <geometry>
        <mesh filename="package://urdf_thor/meshes/art6.stl" scale="0.001 0.001 0.001" />
      </geometry>
      <material name="filament"/>
    </visual>
  </link>

</robot>
