<?xml version="1.0" ?>
<!-- =================================================================================== -->
<!-- |    This document was autogenerated by xacro from /home/pc/Documents/others/Thor-ROS/ws_thor/install/thor_urdf/share/thor_urdf/urdf/thor.urdf.xacro | -->
<!-- |    EDITING THIS FILE BY HAND IS NOT RECOMMENDED                                 | -->
<!-- =================================================================================== -->
<robot name="thor_arm">
	<gazebo>
		<plugin filename="libgazebo_ros2_control.so" name="gazebo_ros2_control">
			<robot_param>robot_description</robot_param>
			<robot_param_node>robot_state_publisher</robot_param_node>
			<parameters>/home/pc/Documents/others/Thor-ROS/ws_thor/install/thor_controller/share/thor_controller/config/thor_controllers.yaml</parameters>
		</plugin>
	</gazebo>
	<ros2_control name="RobotSystem" type="system">
		<!-- HARDWARE -->
		<hardware>
			<plugin>gazebo_ros2_control/GazeboSystem</plugin>
		</hardware>
		<joint name="gripperbase_to_armgearleft">
			<param name="mimic">gripperbase_to_armgearright</param>
			<param name="multiplier">-1</param>
		</joint>
		<joint name="gripperbase_to_armsimpleright">
			<param name="mimic">gripperbase_to_armgearright</param>
			<param name="multiplier">1</param>
		</joint>
		<joint name="gripperbase_to_armsimpleleft">
			<param name="mimic">gripperbase_to_armgearright</param>
			<param name="multiplier">-1</param>
		</joint>
		<joint name="armgearright_to_fingerright">
			<param name="mimic">gripperbase_to_armgearright</param>
			<param name="multiplier">-1</param>
		</joint>
		<joint name="armgearleft_to_fingerleft">
			<param name="mimic">gripperbase_to_armgearright</param>
			<param name="multiplier">-1</param>
		</joint>
		<!-- JOINTS -->
		<joint name="joint_1">
			<command_interface name="position"/>
			<state_interface name="position"/>
		</joint>
		<joint name="joint_2">
			<command_interface name="position"/>
			<state_interface name="position"/>
		</joint>
		<joint name="joint_3">
			<command_interface name="position"/>
			<state_interface name="position"/>
		</joint>
		<joint name="joint_4">
			<command_interface name="position"/>
			<state_interface name="position"/>
		</joint>
		<joint name="joint_5">
			<command_interface name="position"/>
			<state_interface name="position"/>
		</joint>
		<joint name="joint_6">
			<command_interface name="position"/>
			<state_interface name="position"/>
		</joint>
		<joint name="gripperbase_to_armgearright">
			<command_interface name="position"/>
			<state_interface name="position"/>
		</joint>
	</ros2_control>
	<!-- Links -->
	<link name="world"/>
	<link name="base_link">
		<inertial>
			<origin rpy="0 0 0" xyz="0 0 0"/>
			<mass value="1.0"/>
			<inertia ixx="1.0" ixy="0.0" ixz="0.0" iyy="1.0" iyz="0.0" izz="1.0"/>
		</inertial>
		<visual>
			<origin rpy="0 0 -1.570796326795" xyz="0 0 0"/>
			<geometry>
				<mesh filename="package://thor_urdf/meshes/Base.dae" scale="0.001 0.001 0.001"/>
			</geometry>
		</visual>
		<collision>
			<origin rpy="0 0 -1.570796326795" xyz="0 0 0.049"/>
			<geometry>
				<cylinder length="0.098" radius="0.075"/>
			</geometry>
		</collision>
		<collision>
			<origin rpy="0 0 -1.570796326795" xyz="0 -0.1312686 0.035250"/>
			<geometry>
				<box size="0.176 0.180 0.0705"/>
			</geometry>
		</collision>
	</link>
	<link name="link_1">
		<inertial>
			<origin rpy="0 0 0" xyz="0 0 0"/>
			<mass value="1.0"/>
			<inertia ixx="1.0" ixy="0.0" ixz="0.0" iyy="1.0" iyz="0.0" izz="1.0"/>
		</inertial>
		<visual>
			<origin rpy="0 0 -1.570796326795" xyz="0 0 0"/>
			<geometry>
				<mesh filename="package://thor_urdf/meshes/Art1.dae" scale="0.001 0.001 0.001"/>
			</geometry>
		</visual>
		<collision>
			<origin rpy="0 0 -1.570796326795" xyz="0 0 0.0765"/>
			<geometry>
				<cylinder length="0.179" radius="0.075"/>
			</geometry>
		</collision>
	</link>
	<link name="link_2">
		<inertial>
			<origin rpy="0 0 0" xyz="0 0 0"/>
			<mass value="1.0"/>
			<inertia ixx="1.0" ixy="0.0" ixz="0.0" iyy="1.0" iyz="0.0" izz="1.0"/>
		</inertial>
		<visual>
			<origin rpy="0 0 -1.570796326795" xyz="0 0 0"/>
			<geometry>
				<mesh filename="package://thor_urdf/meshes/Art2.dae" scale="0.001 0.001 0.001"/>
			</geometry>
		</visual>
		<collision>
			<origin rpy="1.570796326795 0 -1.570796326795" xyz="0 0 0"/>
			<geometry>
				<cylinder length="0.140" radius="0.065"/>
			</geometry>
		</collision>
		<collision>
			<origin rpy="1.570796326795 0 -1.570796326795" xyz="0 0 0.080"/>
			<geometry>
				<box size="0.130 0.160 0.140"/>
			</geometry>
		</collision>
		<collision>
			<origin rpy="1.570796326795 0 -1.570796326795" xyz="0 0 0.160"/>
			<geometry>
				<cylinder length="0.140" radius="0.065"/>
			</geometry>
		</collision>
	</link>
	<link name="link_3">
		<inertial>
			<origin rpy="0 0 0" xyz="0 0 0"/>
			<mass value="1.0"/>
			<inertia ixx="1.0" ixy="0.0" ixz="0.0" iyy="1.0" iyz="0.0" izz="1.0"/>
		</inertial>
		<visual>
			<origin rpy="0 0 -1.570796326795" xyz="0 0 0"/>
			<geometry>
				<mesh filename="package://thor_urdf/meshes/Art3.dae" scale="0.001 0.001 0.001"/>
			</geometry>
		</visual>
		<collision>
			<origin rpy="0 0 -1.570796326795" xyz="0 0 0.01225"/>
			<geometry>
				<cylinder length="0.1525" radius="0.055"/>
			</geometry>
		</collision>
	</link>
	<link name="link_4">
		<inertial>
			<origin rpy="0 0 0" xyz="0 0 0"/>
			<mass value="1.0"/>
			<inertia ixx="1.0" ixy="0.0" ixz="0.0" iyy="1.0" iyz="0.0" izz="1.0"/>
		</inertial>
		<visual>
			<origin rpy="0 0 -1.570796326795" xyz="0 0 0"/>
			<geometry>
				<mesh filename="package://thor_urdf/meshes/Art4.dae" scale="0.001 0.001 0.001"/>
			</geometry>
		</visual>
		<collision>
			<origin rpy="0 0 -1.570796326795" xyz="0 0 0.1045"/>
			<geometry>
				<sphere radius="0.055"/>
			</geometry>
		</collision>
		<collision>
			<origin rpy="0 0 -1.570796326795" xyz="0 0 0.05525"/>
			<geometry>
				<cylinder length="0.1045" radius="0.055"/>
			</geometry>
		</collision>
		<collision>
			<origin rpy="0 0 -1.570796326795" xyz="0 0 0.0295"/>
			<geometry>
				<box size="0.050 0.132 0.050"/>
			</geometry>
		</collision>
	</link>
	<link name="link_5">
		<inertial>
			<origin rpy="0 0 0" xyz="0 0 0"/>
			<mass value="1.0"/>
			<inertia ixx="1.0" ixy="0.0" ixz="0.0" iyy="1.0" iyz="0.0" izz="1.0"/>
		</inertial>
		<visual>
			<origin rpy="0 0 -1.570796326795" xyz="0 0 0"/>
			<geometry>
				<mesh filename="package://thor_urdf/meshes/Art5.dae" scale="0.001 0.001 0.001"/>
			</geometry>
		</visual>
		<collision>
			<origin rpy="1.570796326795 0 -1.570796326795" xyz="0 0 0"/>
			<geometry>
				<cylinder length="0.03" radius="0.047"/>
			</geometry>
		</collision>
	</link>
	<link name="link_6">
		<inertial>
			<origin rpy="0 0 0" xyz="0 0 0"/>
			<mass value="1.0"/>
			<inertia ixx="1.0" ixy="0.0" ixz="0.0" iyy="1.0" iyz="0.0" izz="1.0"/>
		</inertial>
		<visual>
			<origin rpy="0 0 -1.570796326795" xyz="0 0 0"/>
			<geometry>
				<mesh filename="package://thor_urdf/meshes/Art6.dae" scale="0.001 0.001 0.001"/>
			</geometry>
		</visual>
		<collision>
			<origin rpy="0 0 -1.570796326795" xyz="0 0 0.025"/>
			<geometry>
				<cylinder length="0.05" radius="0.015"/>
			</geometry>
		</collision>
	</link>
	<link name="gripper_base">
		<inertial>
			<origin rpy="0 0 0" xyz="0 0 0"/>
			<mass value="1.0"/>
			<inertia ixx="1.0" ixy="0.0" ixz="0.0" iyy="1.0" iyz="0.0" izz="1.0"/>
		</inertial>
		<visual>
			<origin rpy="0 0 0" xyz="0 0 0"/>
			<geometry>
				<mesh filename="package://thor_urdf/meshes/GripperBase.dae" scale="0.001 0.001 0.001"/>
			</geometry>
		</visual>
		<collision>
			<origin rpy="0 0 0" xyz="0 0 0.0275"/>
			<geometry>
				<box size="0.065 0.0348 0.055"/>
			</geometry>
		</collision>
		<collision>
			<origin rpy="0 0 0" xyz="-0.004250 0.03125 0.0325"/>
			<geometry>
				<box size="0.0406 0.0277 0.020"/>
			</geometry>
		</collision>
	</link>
	<link name="gripper_arm_gear_right">
		<inertial>
			<origin rpy="0 0 0" xyz="0 0 0"/>
			<mass value="1.0"/>
			<inertia ixx="1.0" ixy="0.0" ixz="0.0" iyy="1.0" iyz="0.0" izz="1.0"/>
		</inertial>
		<visual>
			<origin rpy="0 -1.570796326795 1.570796326795" xyz="0 0 0"/>
			<geometry>
				<mesh filename="package://thor_urdf/meshes/GripperArmGear.dae" scale="0.001 0.001 0.001"/>
			</geometry>
		</visual>
		<collision>
			<origin rpy="0 0 0" xyz="0.0175 -0.0025 0.0"/>
			<geometry>
				<box size="0.035 0.005 0.004"/>
			</geometry>
		</collision>
	</link>
	<link name="gripper_arm_gear_left">
		<inertial>
			<origin rpy="0 0 0" xyz="0 0 0"/>
			<mass value="1.0"/>
			<inertia ixx="1.0" ixy="0.0" ixz="0.0" iyy="1.0" iyz="0.0" izz="1.0"/>
		</inertial>
		<visual>
			<origin rpy="0 1.570796326795 -1.570796326795" xyz="0 0 0"/>
			<geometry>
				<mesh filename="package://thor_urdf/meshes/GripperArmGear.dae" scale="0.001 0.001 0.001"/>
			</geometry>
		</visual>
		<collision>
			<origin rpy="0 0 0" xyz="-0.0175 -0.0025 0.0"/>
			<geometry>
				<box size="0.035 0.005 0.004"/>
			</geometry>
		</collision>
	</link>
	<link name="gripper_arm_simple_right">
		<inertial>
			<origin rpy="0 0 0" xyz="0 0 0"/>
			<mass value="1.0"/>
			<inertia ixx="1.0" ixy="0.0" ixz="0.0" iyy="1.0" iyz="0.0" izz="1.0"/>
		</inertial>
		<visual>
			<origin rpy="0 -1.570796326795 1.570796326795" xyz="0 0 0"/>
			<geometry>
				<mesh filename="package://thor_urdf/meshes/GripperArm.dae" scale="0.001 0.001 0.001"/>
			</geometry>
		</visual>
		<collision>
			<origin rpy="0 0 0" xyz="0.0175 -0.0025 0.0"/>
			<geometry>
				<box size="0.035 0.005 0.004"/>
			</geometry>
		</collision>
	</link>
	<link name="gripper_arm_simple_left">
		<inertial>
			<origin rpy="0 0 0" xyz="0 0 0"/>
			<mass value="1.0"/>
			<inertia ixx="1.0" ixy="0.0" ixz="0.0" iyy="1.0" iyz="0.0" izz="1.0"/>
		</inertial>
		<visual>
			<origin rpy="0 1.570796326795 -1.570796326795" xyz="0 0 0"/>
			<geometry>
				<mesh filename="package://thor_urdf/meshes/GripperArm.dae" scale="0.001 0.001 0.001"/>
			</geometry>
		</visual>
		<collision>
			<origin rpy="0 0 0" xyz="-0.0175 -0.0025 0.0"/>
			<geometry>
				<box size="0.035 0.005 0.004"/>
			</geometry>
		</collision>
	</link>
	<link name="gripper_finger_right">
		<inertial>
			<origin rpy="0 0 0" xyz="0 0 0"/>
			<mass value="1.0"/>
			<inertia ixx="1.0" ixy="0.0" ixz="0.0" iyy="1.0" iyz="0.0" izz="1.0"/>
		</inertial>
		<visual>
			<origin rpy="0 0 0" xyz="0 0 0"/>
			<geometry>
				<mesh filename="package://thor_urdf/meshes/GripperFinger.dae" scale="0.001 0.001 0.001"/>
			</geometry>
		</visual>
		<collision>
			<origin rpy="0 0 0" xyz="0.00525 0.026 0.00775"/>
			<geometry>
				<box size="0.0185 0.06 0.0155"/>
			</geometry>
		</collision>
	</link>
	<link name="gripper_finger_left">
		<inertial>
			<origin rpy="0 0 0" xyz="0 0 0"/>
			<mass value="1.0"/>
			<inertia ixx="1.0" ixy="0.0" ixz="0.0" iyy="1.0" iyz="0.0" izz="1.0"/>
		</inertial>
		<visual>
			<origin rpy="0 0 0" xyz="0 0 0"/>
			<geometry>
				<mesh filename="package://thor_urdf/meshes/GripperFinger.dae" scale="0.001 0.001 0.001"/>
			</geometry>
		</visual>
		<collision>
			<origin rpy="0 0 0" xyz="0.00525 0.026 0.00775"/>
			<geometry>
				<box size="0.0185 0.06 0.0155"/>
			</geometry>
		</collision>
	</link>
	<!-- Joints -->
	<joint name="virtual_joint" type="fixed">
		<parent link="world"/>
		<child link="base_link"/>
		<origin rpy="0 0 0" xyz="0 0 0"/>
	</joint>
	<joint name="joint_1" type="revolute">
		<parent link="base_link"/>
		<child link="link_1"/>
		<origin rpy="0 0 0" xyz="0 0 0.099"/>
		<axis xyz="0 0 1"/>
		<limit effort="4.0" lower="-2.967" upper="2.967" velocity="1.0"/>
	</joint>
	<joint name="joint_2" type="revolute">
		<parent link="link_1"/>
		<child link="link_2"/>
		<origin rpy="0 0 0" xyz="0 0 0.103"/>
		<axis xyz="1 0 0"/>
		<limit effort="4.0" lower="-1.570796326795" upper="1.570796326795" velocity="1.0"/>
	</joint>
	<joint name="joint_3" type="revolute">
		<parent link="link_2"/>
		<child link="link_3"/>
		<origin rpy="0 0 0" xyz="0 0 0.16"/>
		<axis xyz="1 0 0"/>
		<limit effort="4.0" lower="-1.570796326795" upper="1.570796326795" velocity="1.0"/>
	</joint>
	<joint name="joint_4" type="revolute">
		<parent link="link_3"/>
		<child link="link_4"/>
		<origin rpy="0 0 0" xyz="0 0 0.0895"/>
		<axis xyz="0 0 1"/>
		<limit effort="4.0" lower="-2.967" upper="2.967" velocity="1.0"/>
	</joint>
	<joint name="joint_5" type="revolute">
		<parent link="link_4"/>
		<child link="link_5"/>
		<origin rpy="0 0 0" xyz="0 0 0.1045"/>
		<axis xyz="1 0 0"/>
		<limit effort="4.0" lower="-1.570796326795" upper="1.570796326795" velocity="1.0"/>
	</joint>
	<joint name="joint_6" type="revolute">
		<parent link="link_5"/>
		<child link="link_6"/>
		<origin rpy="0 0 0" xyz="0 0 0.0135"/>
		<axis xyz="0 0 1"/>
		<limit effort="4.0" lower="-2.967" upper="2.967" velocity="1.0"/>
	</joint>
	<joint name="link6_to_gripperbase" type="fixed">
		<parent link="link_6"/>
		<child link="gripper_base"/>
		<origin xyz="0 0 0.043"/>
	</joint>
	<joint name="gripperbase_to_armgearright" type="revolute">
		<parent link="gripper_base"/>
		<child link="gripper_arm_gear_right"/>
		<origin rpy="0 0 0" xyz="0.0145 0.00275 0.0325"/>
		<axis xyz="0 1 0"/>
		<limit effort="4.0" lower="-1.570796326795" upper="0" velocity="1.0"/>
	</joint>
	<joint name="gripperbase_to_armgearleft" type="revolute">
		<parent link="gripper_base"/>
		<child link="gripper_arm_gear_left"/>
		<origin rpy="0 0 0" xyz="-0.0145 0.00275 0.0325"/>
		<axis xyz="0 1 0"/>
		<limit effort="4.0" lower="0" upper="1.570796326795" velocity="1.0"/>
		<mimic joint="gripperbase_to_armgearright" multiplier="-1"/>
	</joint>
	<joint name="gripperbase_to_armsimpleright" type="revolute">
		<parent link="gripper_base"/>
		<child link="gripper_arm_simple_right"/>
		<origin rpy="0 0 0" xyz="0.006 0.00275 0.051"/>
		<axis xyz="0 1 0"/>
		<limit effort="4.0" lower="-1.570796326795" upper="0" velocity="1.0"/>
		<mimic joint="gripperbase_to_armgearright" multiplier="1"/>
	</joint>
	<joint name="gripperbase_to_armsimpleleft" type="revolute">
		<parent link="gripper_base"/>
		<child link="gripper_arm_simple_left"/>
		<origin rpy="0 0 0" xyz="-0.006 0.00275 0.051"/>
		<axis xyz="0 1 0"/>
		<limit effort="4.0" lower="0" upper="1.570796326795" velocity="1.0"/>
		<mimic joint="gripperbase_to_armgearright" multiplier="-1"/>
	</joint>
	<joint name="armgearright_to_fingerright" type="revolute">
		<parent link="gripper_arm_gear_right"/>
		<child link="gripper_finger_right"/>
		<origin rpy="-1.570796326795 3.14159265359 0" xyz="0.035 -0.01023 0"/>
		<axis xyz="0 0 1"/>
		<limit effort="4.0" lower="0" upper="1.570796326795" velocity="1.0"/>
		<mimic joint="gripperbase_to_armgearright" multiplier="-1"/>
	</joint>
	<joint name="armgearleft_to_fingerleft" type="revolute">
		<parent link="gripper_arm_gear_left"/>
		<child link="gripper_finger_left"/>
		<origin rpy="1.570796326795 0 0" xyz="-0.035 0.005175 0"/>
		<axis xyz="0 0 1"/>
		<limit effort="4.0" lower="0" upper="1.570796326795" velocity="1.0"/>
		<mimic joint="gripperbase_to_armgearright" multiplier="-1"/>
	</joint>
</robot>
