<?xml version="1.0"?>
<robot xmlns:xacro="http://www.ros.org/wiki/xacro" name="thor_arm">

    <!-- Load Simulated or Real Hardware Interfaces -->
    <xacro:arg name="is_sim" default="true"/>

    <!-- Include Gazebo Parameters -->
    <xacro:include filename="$(find thor_urdf)/urdf/thor_gazebo.xacro" />

    <!-- Include ros2_control Plugins -->
    <xacro:include filename="$(find thor_urdf)/urdf/thor_arm.ros2_control.xacro" />

    <!-- Useful XACRO Variables (Properties) -->
    <xacro:property name="PI" value="3.14159265359" />
    <xacro:property name="effort" value="4.0" />
    <xacro:property name="velocity" value="1.0" />

    <!-- Useful Macros -->
    <xacro:macro name="default_inertial" params="mass">
        <inertial>
            <origin xyz="0 0 0" rpy="0 0 0"/>
            <mass value="${mass}" />
            <inertia ixx="1.0" ixy="0.0" ixz="0.0"
                     iyy="1.0" iyz="0.0"
                     izz="1.0" />
        </inertial>
    </xacro:macro>


    <!-- Links -->
    <link name="world"/>

    <link name="base_link">
        <xacro:default_inertial mass="1.0"/>
        <visual>
            <origin xyz="0 0 0" rpy="0 0 -${PI / 2}"/>
            <geometry>
              <mesh filename="package://thor_urdf/meshes/Base.dae" scale="0.001 0.001 0.001" />
            </geometry>
        </visual>
        <collision>
            <origin xyz="0 0 0.049" rpy="0 0 -${PI / 2}"/>
            <geometry>
                <cylinder radius="0.075" length="0.098"/>
            </geometry>
        </collision>
        <collision>
            <origin xyz="0 -0.1312686 0.035250" rpy="0 0 -${PI / 2}"/>
            <geometry>
                <box size="0.176 0.180 0.0705"/>
            </geometry>
        </collision>
    </link>

    <link name="link_1">
        <xacro:default_inertial mass="1.0"/>
        <visual>
            <origin xyz="0 0 0" rpy="0 0 -${PI / 2}"/>
            <geometry>
              <mesh filename="package://thor_urdf/meshes/Art1.dae" scale="0.001 0.001 0.001" />
            </geometry>
        </visual>
        <collision>
            <origin xyz="0 0 0.0765" rpy="0 0 -${PI / 2}"/>
            <geometry>
                <cylinder radius="0.075" length="0.179"/>
            </geometry>
        </collision>
    </link>

    <link name="link_2">
        <xacro:default_inertial mass="1.0"/>
        <visual>
            <origin xyz="0 0 0" rpy="0 0 -${PI / 2}"/>
            <geometry>
              <mesh filename="package://thor_urdf/meshes/Art2.dae" scale="0.001 0.001 0.001" />
            </geometry>
        </visual>
        <collision>
            <origin xyz="0 0 0" rpy="${PI / 2} 0 -${PI / 2}"/>
            <geometry>
                <cylinder radius="0.065" length="0.140"/>
            </geometry>
        </collision>
        <collision>
            <origin xyz="0 0 0.080" rpy="${PI / 2} 0 -${PI / 2}"/>
            <geometry>
                <box size="0.130 0.160 0.140"/>
            </geometry>
        </collision>
        <collision>
            <origin xyz="0 0 0.160" rpy="${PI / 2} 0 -${PI / 2}"/>
            <geometry>
                <cylinder radius="0.065" length="0.140"/>
            </geometry>
        </collision>
    </link>

    <link name="link_3">
        <xacro:default_inertial mass="1.0"/>
        <visual>
            <origin xyz="0 0 0" rpy="0 0 -${PI / 2}"/>
            <geometry>
              <mesh filename="package://thor_urdf/meshes/Art3.dae" scale="0.001 0.001 0.001" />
            </geometry>
        </visual>
        <collision>
            <origin xyz="0 0 0.01225" rpy="0 0 -${PI / 2}"/>
            <geometry>
                <cylinder radius="0.055" length="0.1525"/>
            </geometry>
        </collision>
    </link>

    <link name="link_4">
        <xacro:default_inertial mass="1.0"/>
        <visual>
            <origin xyz="0 0 0" rpy="0 0 -${PI / 2}"/>
            <geometry>
              <mesh filename="package://thor_urdf/meshes/Art4.dae" scale="0.001 0.001 0.001" />
            </geometry>
        </visual>
        <collision>
            <origin xyz="0 0 0.1045" rpy="0 0 -${PI / 2}"/>
            <geometry>
                <sphere radius="0.055"/>
            </geometry>
        </collision>
        <collision>
            <origin xyz="0 0 0.05525" rpy="0 0 -${PI / 2}"/>
            <geometry>
                <cylinder radius="0.055" length="0.1045"/>
            </geometry>
        </collision>
        <collision>
            <origin xyz="0 0 0.0295" rpy="0 0 -${PI / 2}"/>
            <geometry>
                <box size="0.050 0.132 0.050"/>
            </geometry>
        </collision>
    </link>

    <link name="link_5">
        <xacro:default_inertial mass="1.0"/>
        <visual>
            <origin xyz="0 0 0" rpy="0 0 -${PI / 2}"/>
            <geometry>
                <mesh filename="package://thor_urdf/meshes/Art5.dae" scale="0.001 0.001 0.001" />
            </geometry>
        </visual>
        <collision>
            <origin xyz="0 0 0" rpy="${PI / 2} 0 -${PI / 2}"/>
            <geometry>
                <cylinder radius="0.047" length="0.03"/>
            </geometry>
        </collision>
    </link>

    <link name="link_6">
        <xacro:default_inertial mass="1.0"/>
        <visual>
            <origin xyz="0 0 0" rpy="0 0 -${PI / 2}"/>
        <geometry>
            <mesh filename="package://thor_urdf/meshes/Art6.dae" scale="0.001 0.001 0.001" />
        </geometry>
        </visual>
        <collision>
            <origin xyz="0 0 0.025" rpy="0 0 -${PI / 2}"/>
            <geometry>
                <cylinder radius="0.015" length="0.05"/>
            </geometry>
        </collision>
    </link>

    <link name="gripper_base">
        <xacro:default_inertial mass="1.0"/>
        <visual>
            <origin xyz="0 0 0" rpy="0 0 0"/>
        <geometry>
            <mesh filename="package://thor_urdf/meshes/GripperBase.dae" scale="0.001 0.001 0.001" />
        </geometry>
        </visual>
        <collision>
            <origin xyz="0 0 0.0275" rpy="0 0 0"/>
            <geometry>
                <box size="0.065 0.0348 0.055"/>
            </geometry>
        </collision>
        <collision>
            <origin xyz="-0.004250 0.03125 0.0325" rpy="0 0 0"/>
            <geometry>
                <box size="0.0406 0.0277 0.020"/>
            </geometry>
        </collision>
    </link>

    <link name="gripper_mid_point">
        <xacro:default_inertial mass="1.0"/>
    </link>

    <link name="gripper_arm_gear_right">
        <xacro:default_inertial mass="1.0"/>
        <visual>
            <origin xyz="0 0 0" rpy="0 -${PI / 2} ${PI / 2}"/>
        <geometry>
            <mesh filename="package://thor_urdf/meshes/GripperArmGear.dae" scale="0.001 0.001 0.001" />
        </geometry>
        </visual>
        <collision>
            <origin xyz="0.0175 -0.0025 0.0" rpy="0 0 0"/>
            <geometry>
                <box size="0.035 0.005 0.004"/>
            </geometry>
        </collision>
    </link>

    <link name="gripper_arm_gear_left">
        <xacro:default_inertial mass="1.0"/>
        <visual>
            <origin xyz="0 0 0" rpy="0 ${PI / 2} -${PI / 2}"/>
        <geometry>
            <mesh filename="package://thor_urdf/meshes/GripperArmGear.dae" scale="0.001 0.001 0.001" />
        </geometry>
        </visual>
        <collision>
            <origin xyz="-0.0175 -0.0025 0.0" rpy="0 0 0"/>
            <geometry>
                <box size="0.035 0.005 0.004"/>
            </geometry>
        </collision>
    </link>

    <link name="gripper_arm_simple_right">
        <xacro:default_inertial mass="1.0"/>
        <visual>
            <origin xyz="0 0 0" rpy="0 -${PI / 2} ${PI / 2}"/>
        <geometry>
            <mesh filename="package://thor_urdf/meshes/GripperArm.dae" scale="0.001 0.001 0.001" />
        </geometry>
        </visual>
        <collision>
            <origin xyz="0.0175 -0.0025 0.0" rpy="0 0 0"/>
            <geometry>
                <box size="0.035 0.005 0.004"/>
            </geometry>
        </collision>
    </link>

    <link name="gripper_arm_simple_left">
        <xacro:default_inertial mass="1.0"/>
        <visual>
            <origin xyz="0 0 0" rpy="0 ${PI / 2} -${PI / 2}"/>
        <geometry>
            <mesh filename="package://thor_urdf/meshes/GripperArm.dae" scale="0.001 0.001 0.001" />
        </geometry>
        </visual>
        <collision>
            <origin xyz="-0.0175 -0.0025 0.0" rpy="0 0 0"/>
            <geometry>
                <box size="0.035 0.005 0.004"/>
            </geometry>
        </collision>
    </link>

    <link name="gripper_finger_right">
        <xacro:default_inertial mass="1.0"/>
        <visual>
            <origin xyz="0 0 0" rpy="0 0 0"/>
        <geometry>
            <mesh filename="package://thor_urdf/meshes/GripperFinger.dae" scale="0.001 0.001 0.001" />
        </geometry>
        </visual>
        <collision>
            <origin xyz="0.00525 0.026 0.00775" rpy="0 0 0"/>
            <geometry>
                <box size="0.0185 0.06 0.0155"/>
            </geometry>
        </collision>
    </link>

    <link name="gripper_finger_left">
        <xacro:default_inertial mass="1.0"/>
        <visual>
            <origin xyz="0 0 0" rpy="0 0 0"/>
        <geometry>
            <mesh filename="package://thor_urdf/meshes/GripperFinger.dae" scale="0.001 0.001 0.001" />
        </geometry>
        </visual>
        <collision>
            <origin xyz="0.00525 0.026 0.00775" rpy="0 0 0"/>
            <geometry>
                <box size="0.0185 0.06 0.0155"/>
            </geometry>
        </collision>
    </link>


    <!-- Joints -->  
    <joint name="virtual_joint" type="fixed">
        <parent link="world"/>
        <child link="base_link"/>
        <origin xyz="0 0 0" rpy="0 0 0"/>
    </joint> 

    <joint name ="joint_1" type="revolute">
        <parent link="base_link"/>
        <child link="link_1"/>
        <origin xyz="0 0 0.099" rpy="0 0 0"/>
        <axis xyz="0 0 1"/>
        <limit lower="-2.967" upper="2.967" 
               effort="${effort}" velocity="0.58"/>
    </joint>

    <joint name="joint_2" type="revolute">
        <parent link="link_1"/>
        <child link="link_2"/>
        <origin xyz="0 0 0.103" rpy="0 0 0"/>
        <axis xyz="1 0 0"/>
        <limit lower="-${PI / 2}" upper="${PI / 2}"
               effort="${effort}" velocity="0.23"/>
    </joint>

    <joint name="joint_3" type="revolute">
        <parent link="link_2"/>
        <child link="link_3"/>
        <origin xyz="0 0 0.16" rpy="0 0 0"/>
        <axis xyz="1 0 0"/>
        <limit lower="-${PI / 2}" upper="${PI / 2}"
               effort="${effort}" velocity="0.23"/>
    </joint>

    <joint name="joint_4" type="revolute">
        <parent link="link_3"/>
        <child link="link_4"/>
        <origin xyz="0 0 0.0895" rpy="0 0 0"/>
        <axis xyz="0 0 1"/>
        <limit lower="-2.967" upper="2.967"
               effort="${effort}" velocity="0.58"/>
    </joint>

    <joint name="joint_5" type="revolute">
        <parent link="link_4"/>
        <child link="link_5"/>
        <origin xyz="0 0 0.1045" rpy="0 0 0"/>
        <axis xyz="1 0 0"/>
        <limit lower="-${PI / 2}" upper="${PI / 2}"
               effort="${effort}" velocity="1.45"/>
      </joint>

    <joint name="joint_6" type="revolute">
        <parent link="link_5"/>
        <child link="link_6"/>
        <origin xyz="0 0 0.0135" rpy="0 0 0"/>
        <axis xyz="0 0 1"/>
        <limit lower="-2.967" upper="2.967"
               effort="${effort}" velocity="1.45"/>
    </joint>

    <joint name ="link6_to_gripperbase" type="fixed">
        <parent link="link_6"/>
        <child link = "gripper_base"/>
        <origin xyz="0 0 0.043"/>
    </joint>

    <joint name="gripperbase_to_midpoint" type="fixed">
        <parent link="gripper_base"/>
        <child link="gripper_mid_point"/>
        <origin xyz="0 0 0.075" rpy="0 0 0"/>
    </joint>

    <joint name="gripperbase_to_armgearright" type="revolute">
        <parent link="gripper_base"/>
        <child link="gripper_arm_gear_right"/>
        <origin xyz="0.0145 0.00275 0.0325" rpy="0 0 0"/>
        <axis xyz="0 1 0"/>
        <limit lower="-${PI / 2}" upper="0"
               effort="${effort}" velocity="${velocity}"/>
    </joint>

    <joint name="gripperbase_to_armgearleft" type="revolute">
        <parent link="gripper_base"/>
        <child link="gripper_arm_gear_left"/>
        <origin xyz="-0.0145 0.00275 0.0325" rpy="0 0 0"/>
        <axis xyz="0 1 0"/>
        <limit lower="0" upper="${PI / 2}"
               effort="${effort}" velocity="${velocity}"/>
        <mimic joint="gripperbase_to_armgearright" multiplier="-1"/>
    </joint>

    <joint name="gripperbase_to_armsimpleright" type="revolute">
        <parent link="gripper_base"/>
        <child link="gripper_arm_simple_right"/>
        <origin xyz="0.006 0.00275 0.051" rpy="0 0 0"/>
        <axis xyz="0 1 0"/>
        <limit lower="-${PI / 2}" upper="0"
               effort="${effort}" velocity="${velocity}"/>
        <mimic joint="gripperbase_to_armgearright" multiplier="1"/>
    </joint>

    <joint name="gripperbase_to_armsimpleleft" type="revolute">
        <parent link="gripper_base"/>
        <child link="gripper_arm_simple_left"/>
        <origin xyz="-0.006 0.00275 0.051" rpy="0 0 0"/>
        <axis xyz="0 1 0"/>
        <limit lower="0" upper="${PI / 2}"
               effort="${effort}" velocity="${velocity}"/>
        <mimic joint="gripperbase_to_armgearright" multiplier="-1"/>
    </joint>

    <joint name="armgearright_to_fingerright" type="revolute">
        <parent link="gripper_arm_gear_right"/>
        <child link="gripper_finger_right"/>
        <origin xyz="0.035 -0.01023 0" rpy="-${PI / 2} ${PI} 0"/>
        <axis xyz="0 0 1"/>
        <limit lower="0" upper="${PI / 2}"
               effort="${effort}" velocity="${velocity}"/>
        <mimic joint="gripperbase_to_armgearright" multiplier="-1"/>
    </joint>

    <joint name="armgearleft_to_fingerleft" type="revolute">
        <parent link="gripper_arm_gear_left"/>
        <child link="gripper_finger_left"/>
        <origin xyz="-0.035 0.005175 0" rpy="${PI / 2} 0 0"/>
        <axis xyz="0 0 1"/>
        <limit lower="0" upper="${PI / 2}"
               effort="${effort}" velocity="${velocity}"/>
        <mimic joint="gripperbase_to_armgearright" multiplier="-1"/>
    </joint>

</robot>